<?xml version="1.0" ?>
<robot name="romipi" xmlns:xacro="http://ros.org/wiki/xacro">
  <xacro:include filename="$(find romipi_description)/urdf/common_properties.xacro"/>
  <xacro:include filename="$(find romipi_description)/urdf/romipi.gazebo.xacro"/>

  <link name="base_footprint"/>

  <joint name="base_joint" type="fixed">
    <parent link="base_footprint"/>
    <child link="base_link"/>
    <origin xyz="0.0 0.0 0.00" rpy="0 0 0"/>
  </joint>

  <link name="base_link">
    <visual>
      <origin xyz="0.0 0.0 0.0" rpy="0 0 3.14"/>
      <geometry>
        <mesh filename="package://romipi_description/meshes/bases/romi_base.stl" scale="1 1 1"/>
      </geometry>
      <material name="light_black"/>
    </visual>

    <collision>
      <origin xyz="0.0 0.0 0.0315" rpy="0 0 0"/>
      <geometry>
        <box size="0.1635 0.145 0.05"/>
      </geometry>
    </collision>

    <inertial>
      <origin xyz="0 0 0" rpy="0 0 0"/>
      <mass value="8.2573504e-01"/>
      <inertia ixx="2.2124416e-03" ixy="-1.2294101e-05" ixz="3.4938785e-05"
               iyy="2.1193702e-03" iyz="-5.0120904e-06"
               izz="2.0064271e-03" />
    </inertial>
  </link>

  <joint name="wheel_left_joint" type="continuous">
    <parent link="base_link"/>
    <child link="wheel_left_link"/>
    <origin xyz="0.0 0.07 0.0345" rpy="0 0 0"/>
    <axis xyz="0 1 0"/>
  </joint>

  <link name="wheel_left_link">
    <visual>
      <origin xyz="0 0.0 0.0" rpy="3.14 0 0"/>
      <geometry>
        <mesh filename="package://romipi_description/meshes/wheels/romi-left-wheel.stl" scale="1 1 1"/>
      </geometry>
      <material name="dark"/>
    </visual>

    <collision>
      <origin xyz="0 0 0" rpy="1.57 0 0"/>
      <geometry>
        <cylinder length="0.018" radius="0.0345"/>
      </geometry>
    </collision>

    <inertial>
      <origin xyz="0 0 0" />
      <mass value="2.8498940e-02" />
      <inertia ixx="1.1175580e-05" ixy="-4.2369783e-11" ixz="-5.9381719e-09"
               iyy="1.1192413e-05" iyz="-1.4400107e-11"
               izz="2.0712558e-05" />
      </inertial>
  </link>

  <joint name="wheel_right_joint" type="continuous">
    <parent link="base_link"/>
    <child link="wheel_right_link"/>
    <origin xyz="0.0 -0.07 0.0345" rpy="0 0 0"/>
    <axis xyz="0 1 0"/>
  </joint>

  <link name="wheel_right_link">
    <visual>
      <origin xyz="0 0 0" rpy="0 0 0"/>
      <geometry>
        <mesh filename="package://romipi_description/meshes/wheels/romi-right-wheel.stl" scale="1 1 1"/>
      </geometry>
      <material name="dark"/>
    </visual>

    <collision>
      <origin xyz="0 0 0" rpy="1.57 0 0"/>
      <geometry>
        <cylinder length="0.018" radius="0.033"/>
      </geometry>
    </collision>

    <inertial>
      <origin xyz="0 0 0" />
      <mass value="2.8498940e-02" />
      <inertia ixx="1.1175580e-05" ixy="-4.2369783e-11" ixz="-5.9381719e-09"
               iyy="1.1192413e-05" iyz="-1.4400107e-11"
               izz="2.0712558e-05" />
      </inertial>
  </link>

  <joint name="caster_back_joint" type="fixed">
    <parent link="base_link"/>
    <child link="caster_back_link"/>
    <origin xyz="-0.0441 0 0.0" rpy="0 0 0"/>
  </joint>

  <link name="caster_back_link">
    <visual>
      <origin xyz="0 0.0 0.0" rpy="0 0 0"/>
      <geometry>
        <mesh filename="package://romipi_description/meshes/wheels/romi-back-castor.stl" scale="1 1 1"/>
      </geometry>
      <material name="dark"/>
    </visual>

    <collision>
      <origin xyz="0 0.0 0.005" rpy="0 0 0"/>
      <geometry>
        <box size="0.030 0.02 0.01"/>
      </geometry>
    </collision>

    <inertial>
      <origin xyz="0 0 0" />
      <mass value="0.005" />
      <inertia ixx="0.001" ixy="0.0" ixz="0.0"
               iyy="0.001" iyz="0.0"
               izz="0.001" />
    </inertial>
  </link>

  <joint name="imu_joint" type="fixed">
    <parent link="base_link"/>
    <child link="imu_link"/>
    <origin xyz="-0.032 0 0.068" rpy="0 0 0"/>
  </joint>

  <link name="imu_link"/>

</robot>
